Traceback (most recent call last):
  File "run.py", line 2, in <module>
    app.run(host="0.0.0.0", port=80, debug=False)
  File "/usr/local/lib/python2.7/dist-packages/flask/app.py", line 772, in run
    run_simple(host, port, self, **options)
  File "/usr/local/lib/python2.7/dist-packages/werkzeug/serving.py", line 687, in run_simple
    inner()
  File "/usr/local/lib/python2.7/dist-packages/werkzeug/serving.py", line 653, in inner
    fd=fd).serve_forever()
  File "/usr/local/lib/python2.7/dist-packages/werkzeug/serving.py", line 557, in make_server
    passthrough_errors, ssl_context, fd=fd)
  File "/usr/local/lib/python2.7/dist-packages/werkzeug/serving.py", line 467, in __init__
    HTTPServer.__init__(self, (host, int(port)), handler)
  File "/usr/lib/python2.7/SocketServer.py", line 419, in __init__
    self.server_bind()
  File "/usr/lib/python2.7/BaseHTTPServer.py", line 108, in server_bind
    SocketServer.TCPServer.server_bind(self)
  File "/usr/lib/python2.7/SocketServer.py", line 430, in server_bind
    self.socket.bind(self.server_address)
  File "/usr/lib/python2.7/socket.py", line 224, in meth
    return getattr(self._sock,name)(*args)
socket.error: [Errno 98] Address already in use
